Workbook
Name Anio: Dashboard!$D$6
Name ListaCanales: tblCanales[Canal]
Name ListaCategorias: tblCategorias[Categoría]
Name ListaEstados: tblEstados[Estado]
Name ListaModelos: tblModelos[Modelo]
Name ListaMotivos: tblMotivos[Motivo]
Name ListaSKU: tblProductos[SKU]

Sheet Flujo de trabajo
A1: 🎄 Cómo usar este Excel — flujo de trabajo
A2: Sigue los pasos en orden la primera vez; después solo repite la rutina diaria, semanal y mensual.
A4: Paso | B4: Cuándo | C4: Qué hacer | D4: Hoja
A5: A. CONFIGURACIÓN (ya está lista con tus productos y gastos)
A6: 1 | B6: Una vez | C6: Revisa en Productos que el costo, precio, stock inicial (lo que realmente tienes hoy) y stock mínimo de cada pijama sean correctos. Si cambias a un nuevo modelo, agrégalo también en Listas → Modelo. | D6: Productos / Listas
A7: 2 | B7: Una vez | C7: Revisa canales de venta, categorías de gasto, estados y motivos de retiro; agrega los que falten debajo de cada lista y aparecerán en los menús. | D7: Listas
A8: B. RUTINA DIARIA
A9: 3 | B9: Cada venta | C9: En la primera fila vacía debajo de la tabla de Ventas escribe: fecha, pedido, SKU (menú), cantidad, descuento (si hay), canal, cliente y estado. Precio, total, costo y utilidad se llenan solos y el stock baja automáticamente. | D9: Ventas
A10: 4 | B10: Cada venta | C10: Mira la columna «Alerta»: si dice «Stock insuficiente» o «SKU no registrado», corrige antes de seguir. | D10: Ventas
A11: 5 | B11: Al enviar / cobrar | C11: El «Estado» indica el dinero: «Entregado» = ya te pagaron; «Pendiente» = te lo deben. Aparece en el Dashboard como «Dinero cobrado» y «Por cobrar». | D11: Ventas
A12: 6 | B12: Cuando te paguen | C12: Cambia el Estado de ese pedido a «Entregado». Si el monto real es distinto al que estaba estimado, ajusta la columna «Descuento» de la primera fila de ese pedido hasta que el total coincida (descuento negativo = sube el total). | D12: Ventas
A13: 7 | B13: Si hay devolución | C13: Agrega otra fila con el mismo SKU y la cantidad en NEGATIVO (ej. -1). Regresa al inventario y se resta de las ventas. | D13: Ventas
A14: 8 | B14: Cada compra | C14: Cuando llegue mercadería: fecha, SKU, cantidad, costo unitario y proveedor. El stock sube solo. Si es un SKU nuevo, regístralo primero en Productos. | D14: Compras
A15: 9 | B15: Cada gasto | C15: Anota publicidad, envíos, empaque, comisiones, etc. (la compra de mercadería va en Compras y el dinero que sacas para ti va en Retiros, no aquí). | D15: Gastos
A16: 10 | B16: Cada retiro | C16: Cuando saques dinero de las ganancias para ti o para donar (ej. entregar una venta a la iglesia): fecha, concepto, motivo y monto. NO lo anotes en Gastos: así la utilidad del negocio no se distorsiona. | D16: Retiros
A17: C. REVISIÓN SEMANAL
A18: 11 | B18: 1 vez por semana | C18: Abre el Dashboard → «Alertas de reposición» (o filtra Estado = REPONER / AGOTADO en Productos) y haz el pedido al proveedor. | D18: Dashboard / Productos
A19: 12 | B19: 1 vez por semana | C19: Cuenta físicamente las prendas y compáralas con «Stock actual». Si hay diferencia, corrige con una fila en Compras: proveedor «AJUSTE», costo 0 y cantidad positiva o negativa. Compara también «Efectivo estimado en mano» del Dashboard con el dinero que realmente tienes. | D19: Productos / Compras
A20: 13 | B20: 1 vez por semana | C20: Antes de retirar dinero mira en el Dashboard «Disponible para retirar»: es la utilidad que aún no has sacado. Retirar más que eso es usar el dinero que hace falta para reponer mercadería. | D20: Dashboard
A21: D. CIERRE MENSUAL / DE TEMPORADA
A22: 14 | B22: Fin de mes | C22: Revisa en el Dashboard las ventas, utilidad neta, margen, canal que más vende y valor del inventario. Cambia el año en la celda dorada si quieres ver otro año. | D22: Dashboard
A23: 15 | B23: Fin de temporada | C23: Compara la utilidad neta con los retiros: si «Utilidad después de retiros» es positiva, el negocio aguantó lo retirado y quedó ganancia; si es negativa, parte de lo retirado salió del capital. | D23: Dashboard
A24: 16 | B24: Fin de mes | C24: Guarda una copia del archivo con el mes en el nombre (ej. pijamas_2026-12.xlsx) como respaldo. | D24: —
A25: E. REGLAS PARA QUE TODO FUNCIONE
A26: • | B26: Siempre | C26: Todo son TABLAS de Excel: para agregar un registro escribe justo debajo de la última fila (o pulsa Tab en la última celda). La tabla crece sola, copia las fórmulas y los menús, y el Dashboard se actualiza; no hay límite de registros. | D26: —
A27: • | B27: Siempre | C27: Escribe solo en columnas con encabezado VERDE (texto azul). Las de encabezado ROJO son fórmulas automáticas. | D27: —
A28: • | B28: Siempre | C28: No cambies los nombres de las hojas ni de los encabezados de las tablas. Para borrar un registro, clic derecho en su fila → Eliminar → Filas de la tabla. | D28: —
A29: • | B29: Siempre | C29: Gastos = lo que cuesta operar el negocio. Retiros = lo que sacas de las ganancias. No los mezcles. | D29: Gastos / Retiros
A30: • | B30: Siempre | C30: El costo de lo vendido usa el costo actual del catálogo. Si el costo de un modelo cambia mucho, crea un SKU nuevo (ej. PJ-M-M2) para no alterar la utilidad histórica. | D30: Productos
A31: • | B31: Dashboard | C31: Los gráficos muestran hasta 6 canales de venta y 6 categorías de gasto, y la tabla de modelos hasta 5 modelos. Hoja «Datos» = cálculos internos, no editar. | D31: Dashboard / Datos
A33: Colores: | C33: Encabezado verde = tú escribes · Encabezado rojo = fórmula automática · Celda dorada = año del dashboard

Sheet Dashboard
B1: 🎄 DASHBOARD DE NEGOCIO · PIJAMAS 🎄
B3: Inventario · Ventas · Gastos · Retiros ❄ Temporada navideña ❄
B6: AÑO A ANALIZAR | D6: 2026 | E6: ← elige el año con la flecha
B8: VENTAS DEL AÑO | E8: UTILIDAD NETA | H8: GASTOS DEL AÑO | K8: UNIDADES VENDIDAS | N8: VALOR DEL INVENTARIO
B9: =Datos!B63 -> 477 | E9: =Datos!B64 -> 180.25 | H9: =Datos!B65 -> 13 | K9: =Datos!B66 -> 43 | N9: =Datos!B67 -> 476.75
B11: Ticket promedio | D11: =Datos!B70 -> 18.346154 | E11: Margen neto | G11: =Datos!B71 -> 0.3778826 | H11: % de las ventas | J11: =Datos!B72 -> 0.027253669 | K11: Ventas registradas | M11: =Datos!B69 -> 26 | N11: Por reponer | P11: =Datos!B68 -> 6
B13: RETIROS DEL AÑO | E13: UTILIDAD DESPUÉS DE RETIROS | H13: GANANCIA LIBRE PARA RETIRAR | K13: UTILIDAD BRUTA | N13: COMPRAS DE MERCADERÍA
B14: =Datos!B73 -> 51 | E14: =Datos!B75 -> 129.25 | H14: =Datos!B77 -> 129.25 | K14: =Datos!B78 -> 193.25 | N14: =Datos!B80 -> 0
B16: Nº de retiros | D16: =Datos!B74 -> 3 | E16: Retiros / utilidad | G16: =Datos!B76 -> 0.28294036 | H16: Utilidad neta | J16: =Datos!B64 -> 180.25 | K16: Margen bruto | M16: =Datos!B79 -> 0.40513627 | N16: Nº de compras | P16: =Datos!B81 -> 3
B17: =Datos!B82 -> ✔ Los retiros están dentro de la utilidad del negocio.
B19: 💵 DINERO EN CAJA (LO QUE TIENES HOY) | G19: YA COBRADO (ENTREGADO) | L19: POR COBRAR (PENDIENTE)
B20: =Datos!B87 -> 176 | G20: =Datos!B83 -> 240 | L20: =Datos!B85 -> 237
B22: Si cobras lo pendiente serían | F22: =Datos!B88 -> 413 | G22: Pedidos cobrados | K22: =Datos!B84 -> 11 | L22: Registros pendientes | P22: =Datos!B86 -> 15
B23: Dinero en caja = lo ya cobrado − gastos − retiros − compras. NO incluye lo pendiente y NO es ganancia: la mayor parte es dinero para reponer mercadería.
B24: 📈 Ventas, utilidad neta y retiros por mes | K24: 🛍 Ventas por canal
B41: 🎁 Gastos por categoría | H41: 📦 Inventario y ventas por modelo
H42: Modelo | K42: Stock actual | M42: Unid. vendidas (año) | O42: Ventas (año)
H43: =IF(Datos!A38="","",Datos!A38) -> Pijama Mujer | K43: =Datos!B38 -> 33 | M43: =Datos!C38 -> 10 | O43: =Datos!D38 -> 131
H44: =IF(Datos!A39="","",Datos!A39) -> Pijama Niño | K44: =Datos!B39 -> 34 | M44: =Datos!C39 -> 24 | O44: =Datos!D39 -> 237
H45: =IF(Datos!A40="","",Datos!A40) -> Pijama Hombre | K45: =Datos!B40 -> 3 | M45: =Datos!C40 -> 9 | O45: =Datos!D40 -> 109
H46: =IF(Datos!A41="","",Datos!A41) | K46: =Datos!B41 | M46: =Datos!C41 | O46: =Datos!D41
H47: =IF(Datos!A42="","",Datos!A42) | K47: =Datos!B42 | M47: =Datos!C42 | O47: =Datos!D42
H48: TOTAL | K48: =Datos!B43 -> 70 | M48: =Datos!C43 -> 43 | O48: =Datos!D43 -> 477
H50: 🏆 Top 5 más vendidos (acumulado)
H51: # | I51: SKU | K51: Producto | O51: Unidades
H52: 1 | I52: =IF(Datos!F47>0,Datos!D47,"—") -> PJ-N-12 | K52: =IF(Datos!F47>0,Datos!E47,"—") -> Pijama Niño 12 | O52: =Datos!F47 -> 10
H53: 2 | I53: =IF(Datos!F48>0,Datos!D48,"—") -> PJ-N-10 | K53: =IF(Datos!F48>0,Datos!E48,"—") -> Pijama Niño 10 | O53: =Datos!F48 -> 6
H54: 3 | I54: =IF(Datos!F49>0,Datos!D49,"—") -> PJ-N-8 | K54: =IF(Datos!F49>0,Datos!E49,"—") -> Pijama Niño 8 | O54: =Datos!F49 -> 4
H55: 4 | I55: =IF(Datos!F50>0,Datos!D50,"—") -> PJ-M-S | K55: =IF(Datos!F50>0,Datos!E50,"—") -> Pijama Mujer S | O55: =Datos!F50 -> 4
H56: 5 | I56: =IF(Datos!F51>0,Datos!D51,"—") -> PJ-H-S | K56: =IF(Datos!F51>0,Datos!E51,"—") -> Pijama Hombre S | O56: =Datos!F51 -> 3
B58: ⚠ Alertas de reposición
B59: SKU | D59: Producto | I59: Stock actual | K59: Stock mínimo | M59: Estado
B60: =IF(AND(Datos!H55<>"",Datos!H55<>"OK"),Datos!D55,"") -> PJ-N-12 | D60: =IF(Datos!B68=0,"✔ Todo el inventario está en orden",IF(AND(Datos!H55<>"",Datos!H55<>"OK"),Datos!E55,"")) -> Pijama Niño 12 | I60: =IF(AND(Datos!H55<>"",Datos!H55<>"OK"),Datos!F55,"") -> 0 | K60: =IF(AND(Datos!H55<>"",Datos!H55<>"OK"),Datos!G55,"") -> 2 | M60: =IF(AND(Datos!H55<>"",Datos!H55<>"OK"),Datos!H55,"") -> AGOTADO
B61: =IF(AND(Datos!H56<>"",Datos!H56<>"OK"),Datos!D56,"") -> PJ-H-S | D61: =IF(AND(Datos!H56<>"",Datos!H56<>"OK"),Datos!E56,"") -> Pijama Hombre S | I61: =IF(AND(Datos!H56<>"",Datos!H56<>"OK"),Datos!F56,"") -> 0 | K61: =IF(AND(Datos!H56<>"",Datos!H56<>"OK"),Datos!G56,"") -> 1 | M61: =IF(AND(Datos!H56<>"",Datos!H56<>"OK"),Datos!H56,"") -> AGOTADO
B62: =IF(AND(Datos!H57<>"",Datos!H57<>"OK"),Datos!D57,"") -> PJ-H-M | D62: =IF(AND(Datos!H57<>"",Datos!H57<>"OK"),Datos!E57,"") -> Pijama Hombre M | I62: =IF(AND(Datos!H57<>"",Datos!H57<>"OK"),Datos!F57,"") -> 0 | K62: =IF(AND(Datos!H57<>"",Datos!H57<>"OK"),Datos!G57,"") -> 1 | M62: =IF(AND(Datos!H57<>"",Datos!H57<>"OK"),Datos!H57,"") -> AGOTADO
B63: =IF(AND(Datos!H58<>"",Datos!H58<>"OK"),Datos!D58,"") -> PJ-H-L | D63: =IF(AND(Datos!H58<>"",Datos!H58<>"OK"),Datos!E58,"") -> Pijama Hombre L | I63: =IF(AND(Datos!H58<>"",Datos!H58<>"OK"),Datos!F58,"") -> 1 | K63: =IF(AND(Datos!H58<>"",Datos!H58<>"OK"),Datos!G58,"") -> 1 | M63: =IF(AND(Datos!H58<>"",Datos!H58<>"OK"),Datos!H58,"") -> REPONER
B64: =IF(AND(Datos!H59<>"",Datos!H59<>"OK"),Datos!D59,"") -> PJ-H-XL | D64: =IF(AND(Datos!H59<>"",Datos!H59<>"OK"),Datos!E59,"") -> Pijama Hombre XL | I64: =IF(AND(Datos!H59<>"",Datos!H59<>"OK"),Datos!F59,"") -> 1 | K64: =IF(AND(Datos!H59<>"",Datos!H59<>"OK"),Datos!G59,"") -> 1 | M64: =IF(AND(Datos!H59<>"",Datos!H59<>"OK"),Datos!H59,"") -> REPONER
B66: 🎅 ¡Felices fiestas y muchas ventas! 🎁

Sheet Productos
A1: Catálogo e inventario
A2: Encabezado VERDE = tú escribes (texto azul) · Encabezado ROJO = fórmula automática, no la borres. Para agregar un registro escribe en la fila justo debajo de la tabla: ella crece sola.
A4: SKU | B4: Producto | C4: Talla | D4: Color | E4: Costo unitario | F4: Precio venta | G4: Stock inicial | H4: Stock mínimo | I4: Entradas | J4: Salidas | K4: Stock actual | L4: Estado | M4: Valor inventario | N4: Margen
A5: PJ-M-S | B5: Pijama Mujer | C5: S | D5: Verde | E5: 8.5 | F5: 12 | G5: 10 | H5: 2 | I5: =SUMIFS(tblCompras[Cantidad],tblCompras[SKU],tblProductos[[#This Row],[SKU]]) -> 0 | J5: =SUMIFS(tblVentas[Cantidad],tblVentas[SKU],tblProductos[[#This Row],[SKU]]) -> 4 | K5: =tblProductos[[#This Row],[Stock inicial]]+tblProductos[[#This Row],[Entradas]]-tblProductos[[#This Row],[Salidas]] -> 6 | L5: =IF(tblProductos[[#This Row],[SKU]]="","",IF(tblProductos[[#This Row],[Stock actual]]<=0,"AGOTADO",IF(tblProductos[[#This Row],[Stock actual]]<=tblProductos[[#This Row],[Stock mínimo]],"REPONER","OK"))) -> OK | M5: =tblProductos[[#This Row],[Stock actual]]*tblProductos[[#This Row],[Costo unitario]] -> 51 | N5: =IF(tblProductos[[#This Row],[Precio venta]]=0,"",(tblProductos[[#This Row],[Precio venta]]-tblProductos[[#This Row],[Costo unitario]])/tblProductos[[#This Row],[Precio venta]]) -> 0.29166667
A6: PJ-M-M | B6: Pijama Mujer | C6: M | D6: Verde | E6: 8.5 | F6: 12 | G6: 10 | H6: 2 | I6: =SUMIFS(tblCompras[Cantidad],tblCompras[SKU],tblProductos[[#This Row],[SKU]]) -> 0 | J6: =SUMIFS(tblVentas[Cantidad],tblVentas[SKU],tblProductos[[#This Row],[SKU]]) -> 3 | K6: =tblProductos[[#This Row],[Stock inicial]]+tblProductos[[#This Row],[Entradas]]-tblProductos[[#This Row],[Salidas]] -> 7 | L6: =IF(tblProductos[[#This Row],[SKU]]="","",IF(tblProductos[[#This Row],[Stock actual]]<=0,"AGOTADO",IF(tblProductos[[#This Row],[Stock actual]]<=tblProductos[[#This Row],[Stock mínimo]],"REPONER","OK"))) -> OK | M6: =tblProductos[[#This Row],[Stock actual]]*tblProductos[[#This Row],[Costo unitario]] -> 59.5 | N6: =IF(tblProductos[[#This Row],[Precio venta]]=0,"",(tblProductos[[#This Row],[Precio venta]]-tblProductos[[#This Row],[Costo unitario]])/tblProductos[[#This Row],[Precio venta]]) -> 0.29166667
A7: PJ-M-L | B7: Pijama Mujer | C7: L | D7: Verde | E7: 8.5 | F7: 12 | G7: 10 | H7: 2 | I7: =SUMIFS(tblCompras[Cantidad],tblCompras[SKU],tblProductos[[#This Row],[SKU]]) -> -2 | J7: =SUMIFS(tblVentas[Cantidad],tblVentas[SKU],tblProductos[[#This Row],[SKU]]) -> 1 | K7: =tblProductos[[#This Row],[Stock inicial]]+tblProductos[[#This Row],[Entradas]]-tblProductos[[#This Row],[Salidas]] -> 7 | L7: =IF(tblProductos[[#This Row],[SKU]]="","",IF(tblProductos[[#This Row],[Stock actual]]<=0,"AGOTADO",IF(tblProductos[[#This Row],[Stock actual]]<=tblProductos[[#This Row],[Stock mínimo]],"REPONER","OK"))) -> OK | M7: =tblProductos[[#This Row],[Stock actual]]*tblProductos[[#This Row],[Costo unitario]] -> 59.5 | N7: =IF(tblProductos[[#This Row],[Precio venta]]=0,"",(tblProductos[[#This Row],[Precio venta]]-tblProductos[[#This Row],[Costo unitario]])/tblProductos[[#This Row],[Precio venta]]) -> 0.29166667
A8: PJ-M-XL | B8: Pijama Mujer | C8: XL | D8: Verde | E8: 8.5 | F8: 12 | G8: 10 | H8: 2 | I8: =SUMIFS(tblCompras[Cantidad],tblCompras[SKU],tblProductos[[#This Row],[SKU]]) -> 0 | J8: =SUMIFS(tblVentas[Cantidad],tblVentas[SKU],tblProductos[[#This Row],[SKU]]) -> 2 | K8: =tblProductos[[#This Row],[Stock inicial]]+tblProductos[[#This Row],[Entradas]]-tblProductos[[#This Row],[Salidas]] -> 8 | L8: =IF(tblProductos[[#This Row],[SKU]]="","",IF(tblProductos[[#This Row],[Stock actual]]<=0,"AGOTADO",IF(tblProductos[[#This Row],[Stock actual]]<=tblProductos[[#This Row],[Stock mínimo]],"REPONER","OK"))) -> OK | M8: =tblProductos[[#This Row],[Stock actual]]*tblProductos[[#This Row],[Costo unitario]] -> 68 | N8: =IF(tblProductos[[#This Row],[Precio venta]]=0,"",(tblProductos[[#This Row],[Precio venta]]-tblProductos[[#This Row],[Costo unitario]])/tblProductos[[#This Row],[Precio venta]]) -> 0.29166667
A9: PJ-M-XXL | B9: Pijama Mujer | C9: XXL | D9: Verde | E9: 8.5 | F9: 12 | G9: 5 | H9: 1 | I9: =SUMIFS(tblCompras[Cantidad],tblCompras[SKU],tblProductos[[#This Row],[SKU]]) -> 0 | J9: =SUMIFS(tblVentas[Cantidad],tblVentas[SKU],tblProductos[[#This Row],[SKU]]) -> 0 | K9: =tblProductos[[#This Row],[Stock inicial]]+tblProductos[[#This Row],[Entradas]]-tblProductos[[#This Row],[Salidas]] -> 5 | L9: =IF(tblProductos[[#This Row],[SKU]]="","",IF(tblProductos[[#This Row],[Stock actual]]<=0,"AGOTADO",IF(tblProductos[[#This Row],[Stock actual]]<=tblProductos[[#This Row],[Stock mínimo]],"REPONER","OK"))) -> OK | M9: =tblProductos[[#This Row],[Stock actual]]*tblProductos[[#This Row],[Costo unitario]] -> 42.5 | N9: =IF(tblProductos[[#This Row],[Precio venta]]=0,"",(tblProductos[[#This Row],[Precio venta]]-tblProductos[[#This Row],[Costo unitario]])/tblProductos[[#This Row],[Precio venta]]) -> 0.29166667
A10: PJ-N-4 | B10: Pijama Niño | C10: 4 | D10: Verde | E10: 5 | F10: 10 | G10: 10 | H10: 2 | I10: =SUMIFS(tblCompras[Cantidad],tblCompras[SKU],tblProductos[[#This Row],[SKU]]) -> -2 | J10: =SUMIFS(tblVentas[Cantidad],tblVentas[SKU],tblProductos[[#This Row],[SKU]]) -> 0 | K10: =tblProductos[[#This Row],[Stock inicial]]+tblProductos[[#This Row],[Entradas]]-tblProductos[[#This Row],[Salidas]] -> 8 | L10: =IF(tblProductos[[#This Row],[SKU]]="","",IF(tblProductos[[#This Row],[Stock actual]]<=0,"AGOTADO",IF(tblProductos[[#This Row],[Stock actual]]<=tblProductos[[#This Row],[Stock mínimo]],"REPONER","OK"))) -> OK | M10: =tblProductos[[#This Row],[Stock actual]]*tblProductos[[#This Row],[Costo unitario]] -> 40 | N10: =IF(tblProductos[[#This Row],[Precio venta]]=0,"",(tblProductos[[#This Row],[Precio venta]]-tblProductos[[#This Row],[Costo unitario]])/tblProductos[[#This Row],[Precio venta]]) -> 0.5
A11: PJ-N-6 | B11: Pijama Niño | C11: 6 | D11: Verde | E11: 5 | F11: 10 | G11: 10 | H11: 2 | I11: =SUMIFS(tblCompras[Cantidad],tblCompras[SKU],tblProductos[[#This Row],[SKU]]) -> 0 | J11: =SUMIFS(tblVentas[Cantidad],tblVentas[SKU],tblProductos[[#This Row],[SKU]]) -> 2 | K11: =tblProductos[[#This Row],[Stock inicial]]+tblProductos[[#This Row],[Entradas]]-tblProductos[[#This Row],[Salidas]] -> 8 | L11: =IF(tblProductos[[#This Row],[SKU]]="","",IF(tblProductos[[#This Row],[Stock actual]]<=0,"AGOTADO",IF(tblProductos[[#This Row],[Stock actual]]<=tblProductos[[#This Row],[Stock mínimo]],"REPONER","OK"))) -> OK | M11: =tblProductos[[#This Row],[Stock actual]]*tblProductos[[#This Row],[Costo unitario]] -> 40 | N11: =IF(tblProductos[[#This Row],[Precio venta]]=0,"",(tblProductos[[#This Row],[Precio venta]]-tblProductos[[#This Row],[Costo unitario]])/tblProductos[[#This Row],[Precio venta]]) -> 0.5
A12: PJ-N-8 | B12: Pijama Niño | C12: 8 | D12: Verde | E12: 5 | F12: 10 | G12: 10 | H12: 2 | I12: =SUMIFS(tblCompras[Cantidad],tblCompras[SKU],tblProductos[[#This Row],[SKU]]) -> 0 | J12: =SUMIFS(tblVentas[Cantidad],tblVentas[SKU],tblProductos[[#This Row],[SKU]]) -> 4 | K12: =tblProductos[[#This Row],[Stock inicial]]+tblProductos[[#This Row],[Entradas]]-tblProductos[[#This Row],[Salidas]] -> 6 | L12: =IF(tblProductos[[#This Row],[SKU]]="","",IF(tblProductos[[#This Row],[Stock actual]]<=0,"AGOTADO",IF(tblProductos[[#This Row],[Stock actual]]<=tblProductos[[#This Row],[Stock mínimo]],"REPONER","OK"))) -> OK | M12: =tblProductos[[#This Row],[Stock actual]]*tblProductos[[#This Row],[Costo unitario]] -> 30 | N12: =IF(tblProductos[[#This Row],[Precio venta]]=0,"",(tblProductos[[#This Row],[Precio venta]]-tblProductos[[#This Row],[Costo unitario]])/tblProductos[[#This Row],[Precio venta]]) -> 0.5
A13: PJ-N-10 | B13: Pijama Niño | C13: 10 | D13: Verde | E13: 5 | F13: 10 | G13: 10 | H13: 2 | I13: =SUMIFS(tblCompras[Cantidad],tblCompras[SKU],tblProductos[[#This Row],[SKU]]) -> 0 | J13: =SUMIFS(tblVentas[Cantidad],tblVentas[SKU],tblProductos[[#This Row],[SKU]]) -> 6 | K13: =tblProductos[[#This Row],[Stock inicial]]+tblProductos[[#This Row],[Entradas]]-tblProductos[[#This Row],[Salidas]] -> 4 | L13: =IF(tblProductos[[#This Row],[SKU]]="","",IF(tblProductos[[#This Row],[Stock actual]]<=0,"AGOTADO",IF(tblProductos[[#This Row],[Stock actual]]<=tblProductos[[#This Row],[Stock mínimo]],"REPONER","OK"))) -> OK | M13: =tblProductos[[#This Row],[Stock actual]]*tblProductos[[#This Row],[Costo unitario]] -> 20 | N13: =IF(tblProductos[[#This Row],[Precio venta]]=0,"",(tblProductos[[#This Row],[Precio venta]]-tblProductos[[#This Row],[Costo unitario]])/tblProductos[[#This Row],[Precio venta]]) -> 0.5
A14: PJ-N-12 | B14: Pijama Niño | C14: 12 | D14: Verde | E14: 5 | F14: 10 | G14: 10 | H14: 2 | I14: =SUMIFS(tblCompras[Cantidad],tblCompras[SKU],tblProductos[[#This Row],[SKU]]) -> 0 | J14: =SUMIFS(tblVentas[Cantidad],tblVentas[SKU],tblProductos[[#This Row],[SKU]]) -> 10 | K14: =tblProductos[[#This Row],[Stock inicial]]+tblProductos[[#This Row],[Entradas]]-tblProductos[[#This Row],[Salidas]] -> 0 | L14: =IF(tblProductos[[#This Row],[SKU]]="","",IF(tblProductos[[#This Row],[Stock actual]]<=0,"AGOTADO",IF(tblProductos[[#This Row],[Stock actual]]<=tblProductos[[#This Row],[Stock mínimo]],"REPONER","OK"))) -> AGOTADO | M14: =tblProductos[[#This Row],[Stock actual]]*tblProductos[[#This Row],[Costo unitario]] -> 0 | N14: =IF(tblProductos[[#This Row],[Precio venta]]=0,"",(tblProductos[[#This Row],[Precio venta]]-tblProductos[[#This Row],[Costo unitario]])/tblProductos[[#This Row],[Precio venta]]) -> 0.5
A15: PJ-N-14 | B15: Pijama Niño | C15: 14 | D15: Verde | E15: 5 | F15: 10 | G15: 10 | H15: 2 | I15: =SUMIFS(tblCompras[Cantidad],tblCompras[SKU],tblProductos[[#This Row],[SKU]]) -> 0 | J15: =SUMIFS(tblVentas[Cantidad],tblVentas[SKU],tblProductos[[#This Row],[SKU]]) -> 2 | K15: =tblProductos[[#This Row],[Stock inicial]]+tblProductos[[#This Row],[Entradas]]-tblProductos[[#This Row],[Salidas]] -> 8 | L15: =IF(tblProductos[[#This Row],[SKU]]="","",IF(tblProductos[[#This Row],[Stock actual]]<=0,"AGOTADO",IF(tblProductos[[#This Row],[Stock actual]]<=tblProductos[[#This Row],[Stock mínimo]],"REPONER","OK"))) -> OK | M15: =tblProductos[[#This Row],[Stock actual]]*tblProductos[[#This Row],[Costo unitario]] -> 40 | N15: =IF(tblProductos[[#This Row],[Precio venta]]=0,"",(tblProductos[[#This Row],[Precio venta]]-tblProductos[[#This Row],[Costo unitario]])/tblProductos[[#This Row],[Precio venta]]) -> 0.5
A16: PJ-H-S | B16: Pijama Hombre | C16: S | D16: Verde | E16: 8.75 | F16: 12 | G16: 3 | H16: 1 | I16: =SUMIFS(tblCompras[Cantidad],tblCompras[SKU],tblProductos[[#This Row],[SKU]]) -> 0 | J16: =SUMIFS(tblVentas[Cantidad],tblVentas[SKU],tblProductos[[#This Row],[SKU]]) -> 3 | K16: =tblProductos[[#This Row],[Stock inicial]]+tblProductos[[#This Row],[Entradas]]-tblProductos[[#This Row],[Salidas]] -> 0 | L16: =IF(tblProductos[[#This Row],[SKU]]="","",IF(tblProductos[[#This Row],[Stock actual]]<=0,"AGOTADO",IF(tblProductos[[#This Row],[Stock actual]]<=tblProductos[[#This Row],[Stock mínimo]],"REPONER","OK"))) -> AGOTADO | M16: =tblProductos[[#This Row],[Stock actual]]*tblProductos[[#This Row],[Costo unitario]] -> 0 | N16: =IF(tblProductos[[#This Row],[Precio venta]]=0,"",(tblProductos[[#This Row],[Precio venta]]-tblProductos[[#This Row],[Costo unitario]])/tblProductos[[#This Row],[Precio venta]]) -> 0.27083333
A17: PJ-H-M | B17: Pijama Hombre | C17: M | D17: Verde | E17: 8.75 | F17: 12 | G17: 3 | H17: 1 | I17: =SUMIFS(tblCompras[Cantidad],tblCompras[SKU],tblProductos[[#This Row],[SKU]]) -> -3 | J17: =SUMIFS(tblVentas[Cantidad],tblVentas[SKU],tblProductos[[#This Row],[SKU]]) -> 0 | K17: =tblProductos[[#This Row],[Stock inicial]]+tblProductos[[#This Row],[Entradas]]-tblProductos[[#This Row],[Salidas]] -> 0 | L17: =IF(tblProductos[[#This Row],[SKU]]="","",IF(tblProductos[[#This Row],[Stock actual]]<=0,"AGOTADO",IF(tblProductos[[#This Row],[Stock actual]]<=tblProductos[[#This Row],[Stock mínimo]],"REPONER","OK"))) -> AGOTADO | M17: =tblProductos[[#This Row],[Stock actual]]*tblProductos[[#This Row],[Costo unitario]] -> 0 | N17: =IF(tblProductos[[#This Row],[Precio venta]]=0,"",(tblProductos[[#This Row],[Precio venta]]-tblProductos[[#This Row],[Costo unitario]])/tblProductos[[#This Row],[Precio venta]]) -> 0.27083333
A18: PJ-H-L | B18: Pijama Hombre | C18: L | D18: Verde | E18: 8.75 | F18: 12 | G18: 3 | H18: 1 | I18: =SUMIFS(tblCompras[Cantidad],tblCompras[SKU],tblProductos[[#This Row],[SKU]]) -> 0 | J18: =SUMIFS(tblVentas[Cantidad],tblVentas[SKU],tblProductos[[#This Row],[SKU]]) -> 2 | K18: =tblProductos[[#This Row],[Stock inicial]]+tblProductos[[#This Row],[Entradas]]-tblProductos[[#This Row],[Salidas]] -> 1 | L18: =IF(tblProductos[[#This Row],[SKU]]="","",IF(tblProductos[[#This Row],[Stock actual]]<=0,"AGOTADO",IF(tblProductos[[#This Row],[Stock actual]]<=tblProductos[[#This Row],[Stock mínimo]],"REPONER","OK"))) -> REPONER | M18: =tblProductos[[#This Row],[Stock actual]]*tblProductos[[#This Row],[Costo unitario]] -> 8.75 | N18: =IF(tblProductos[[#This Row],[Precio venta]]=0,"",(tblProductos[[#This Row],[Precio venta]]-tblProductos[[#This Row],[Costo unitario]])/tblProductos[[#This Row],[Precio venta]]) -> 0.27083333
A19: PJ-H-XL | B19: Pijama Hombre | C19: XL | D19: Verde | E19: 8.75 | F19: 12 | G19: 3 | H19: 1 | I19: =SUMIFS(tblCompras[Cantidad],tblCompras[SKU],tblProductos[[#This Row],[SKU]]) -> 0 | J19: =SUMIFS(tblVentas[Cantidad],tblVentas[SKU],tblProductos[[#This Row],[SKU]]) -> 2 | K19: =tblProductos[[#This Row],[Stock inicial]]+tblProductos[[#This Row],[Entradas]]-tblProductos[[#This Row],[Salidas]] -> 1 | L19: =IF(tblProductos[[#This Row],[SKU]]="","",IF(tblProductos[[#This Row],[Stock actual]]<=0,"AGOTADO",IF(tblProductos[[#This Row],[Stock actual]]<=tblProductos[[#This Row],[Stock mínimo]],"REPONER","OK"))) -> REPONER | M19: =tblProductos[[#This Row],[Stock actual]]*tblProductos[[#This Row],[Costo unitario]] -> 8.75 | N19: =IF(tblProductos[[#This Row],[Precio venta]]=0,"",(tblProductos[[#This Row],[Precio venta]]-tblProductos[[#This Row],[Costo unitario]])/tblProductos[[#This Row],[Precio venta]]) -> 0.27083333
A20: PJ-H-XXL | B20: Pijama Hombre | C20: XXL | D20: Verde | E20: 8.75 | F20: 12 | G20: 3 | H20: 1 | I20: =SUMIFS(tblCompras[Cantidad],tblCompras[SKU],tblProductos[[#This Row],[SKU]]) -> 0 | J20: =SUMIFS(tblVentas[Cantidad],tblVentas[SKU],tblProductos[[#This Row],[SKU]]) -> 2 | K20: =tblProductos[[#This Row],[Stock inicial]]+tblProductos[[#This Row],[Entradas]]-tblProductos[[#This Row],[Salidas]] -> 1 | L20: =IF(tblProductos[[#This Row],[SKU]]="","",IF(tblProductos[[#This Row],[Stock actual]]<=0,"AGOTADO",IF(tblProductos[[#This Row],[Stock actual]]<=tblProductos[[#This Row],[Stock mínimo]],"REPONER","OK"))) -> REPONER | M20: =tblProductos[[#This Row],[Stock actual]]*tblProductos[[#This Row],[Costo unitario]] -> 8.75 | N20: =IF(tblProductos[[#This Row],[Precio venta]]=0,"",(tblProductos[[#This Row],[Precio venta]]-tblProductos[[#This Row],[Costo unitario]])/tblProductos[[#This Row],[Precio venta]]) -> 0.27083333

Sheet Compras
A1: Compras / entradas de mercadería
A2: Encabezado VERDE = tú escribes (texto azul) · Encabezado ROJO = fórmula automática, no la borres. Para agregar un registro escribe en la fila justo debajo de la tabla: ella crece sola. Para ajustes de inventario usa proveedor «AJUSTE», costo 0 y cantidad + o −.
A4: Fecha | B4: SKU | C4: Producto | D4: Cantidad | E4: Costo unitario | F4: Total | G4: Proveedor
A5: 46321 | B5: PJ-H-M | C5: =IF(tblCompras[[#This Row],[SKU]]="","",IFERROR(INDEX(tblProductos[Producto],MATCH(tblCompras[[#This Row],[SKU]],tblProductos[SKU],0))&" "&INDEX(tblProductos[Talla],MATCH(tblCompras[[#This Row],[SKU]],tblProductos[SKU],0)),"SKU no existe")) -> Pijama Hombre M | D5: -3 | E5: 0 | F5: =IF(OR(tblCompras[[#This Row],[Cantidad]]="",tblCompras[[#This Row],[Costo unitario]]=""),"",tblCompras[[#This Row],[Cantidad]]*tblCompras[[#This Row],[Costo unitario]]) -> 0 | G5: AJUSTE (salida sin registro)
A6: 46321 | B6: PJ-M-L | C6: =IF(tblCompras[[#This Row],[SKU]]="","",IFERROR(INDEX(tblProductos[Producto],MATCH(tblCompras[[#This Row],[SKU]],tblProductos[SKU],0))&" "&INDEX(tblProductos[Talla],MATCH(tblCompras[[#This Row],[SKU]],tblProductos[SKU],0)),"SKU no existe")) -> Pijama Mujer L | D6: -2 | E6: 0 | F6: =IF(OR(tblCompras[[#This Row],[Cantidad]]="",tblCompras[[#This Row],[Costo unitario]]=""),"",tblCompras[[#This Row],[Cantidad]]*tblCompras[[#This Row],[Costo unitario]]) -> 0 | G6: AJUSTE (salida sin registro)
A7: 46321 | B7: PJ-N-4 | C7: =IF(tblCompras[[#This Row],[SKU]]="","",IFERROR(INDEX(tblProductos[Producto],MATCH(tblCompras[[#This Row],[SKU]],tblProductos[SKU],0))&" "&INDEX(tblProductos[Talla],MATCH(tblCompras[[#This Row],[SKU]],tblProductos[SKU],0)),"SKU no existe")) -> Pijama Niño 4 | D7: -2 | E7: 0 | F7: =IF(OR(tblCompras[[#This Row],[Cantidad]]="",tblCompras[[#This Row],[Costo unitario]]=""),"",tblCompras[[#This Row],[Cantidad]]*tblCompras[[#This Row],[Costo unitario]]) -> 0 | G7: AJUSTE (salida sin registro)

Sheet Ventas
A1: Registro de ventas
A2: Encabezado VERDE = tú escribes (texto azul) · Encabezado ROJO = fórmula automática, no la borres. Para agregar un registro escribe en la fila justo debajo de la tabla: ella crece sola. El precio sale del catálogo (puedes escribir encima si vendiste a otro precio). Devolución = misma venta con cantidad NEGATIVA.
A4: Fecha | B4: Pedido | C4: SKU | D4: Producto | E4: Cantidad | F4: Precio unitario | G4: Descuento | H4: Total venta | I4: Costo | J4: Utilidad | K4: Canal | L4: Cliente | M4: Estado | N4: Alerta
A5: 46309 | B5: 1 | C5: PJ-N-10 | D5: =IF(tblVentas[[#This Row],[SKU]]="","",IFERROR(INDEX(tblProductos[Producto],MATCH(tblVentas[[#This Row],[SKU]],tblProductos[SKU],0))&" "&INDEX(tblProductos[Talla],MATCH(tblVentas[[#This Row],[SKU]],tblProductos[SKU],0)),"SKU no existe")) -> Pijama Niño 10 | E5: 1 | F5: =IF(tblVentas[[#This Row],[SKU]]="","",IFERROR(INDEX(tblProductos[Precio venta],MATCH(tblVentas[[#This Row],[SKU]],tblProductos[SKU],0)),0)) -> 10 | G5: -2 | H5: =IF(OR(tblVentas[[#This Row],[SKU]]="",tblVentas[[#This Row],[Cantidad]]=""),"",tblVentas[[#This Row],[Cantidad]]*tblVentas[[#This Row],[Precio unitario]]-tblVentas[[#This Row],[Descuento]]) -> 12 | I5: =IF(OR(tblVentas[[#This Row],[SKU]]="",tblVentas[[#This Row],[Cantidad]]=""),"",tblVentas[[#This Row],[Cantidad]]*IFERROR(INDEX(tblProductos[Costo unitario],MATCH(tblVentas[[#This Row],[SKU]],tblProductos[SKU],0)),0)) -> 5 | J5: =IF(tblVentas[[#This Row],[Total venta]]="","",tblVentas[[#This Row],[Total venta]]-tblVentas[[#This Row],[Costo]]) -> 7 | K5: WhatsApp | L5: Polinaria | M5: Entregado | N5: =IF(tblVentas[[#This Row],[SKU]]="","",IF(ISNA(MATCH(tblVentas[[#This Row],[SKU]],tblProductos[SKU],0)),"SKU no registrado",IF(INDEX(tblProductos[Stock actual],MATCH(tblVentas[[#This Row],[SKU]],tblProductos[SKU],0))<0,"Stock insuficiente","")))
A6: 46309 | B6: 1 | C6: PJ-N-12 | D6: =IF(tblVentas[[#This Row],[SKU]]="","",IFERROR(INDEX(tblProductos[Producto],MATCH(tblVentas[[#This Row],[SKU]],tblProductos[SKU],0))&" "&INDEX(tblProductos[Talla],MATCH(tblVentas[[#This Row],[SKU]],tblProductos[SKU],0)),"SKU no existe")) -> Pijama Niño 12 | E6: 1 | F6: =IF(tblVentas[[#This Row],[SKU]]="","",IFERROR(INDEX(tblProductos[Precio venta],MATCH(tblVentas[[#This Row],[SKU]],tblProductos[SKU],0)),0)) -> 10 | G6: -2 | H6: =IF(OR(tblVentas[[#This Row],[SKU]]="",tblVentas[[#This Row],[Cantidad]]=""),"",tblVentas[[#This Row],[Cantidad]]*tblVentas[[#This Row],[Precio unitario]]-tblVentas[[#This Row],[Descuento]]) -> 12 | I6: =IF(OR(tblVentas[[#This Row],[SKU]]="",tblVentas[[#This Row],[Cantidad]]=""),"",tblVentas[[#This Row],[Cantidad]]*IFERROR(INDEX(tblProductos[Costo unitario],MATCH(tblVentas[[#This Row],[SKU]],tblProductos[SKU],0)),0)) -> 5 | J6: =IF(tblVentas[[#This Row],[Total venta]]="","",tblVentas[[#This Row],[Total venta]]-tblVentas[[#This Row],[Costo]]) -> 7 | K6: WhatsApp | L6: Polinaria | M6: Entregado | N6: =IF(tblVentas[[#This Row],[SKU]]="","",IF(ISNA(MATCH(tblVentas[[#This Row],[SKU]],tblProductos[SKU],0)),"SKU no registrado",IF(INDEX(tblProductos[Stock actual],MATCH(tblVentas[[#This Row],[SKU]],tblProductos[SKU],0))<0,"Stock insuficiente","")))
A7: 46312 | B7: 2 | C7: PJ-N-10 | D7: =IF(tblVentas[[#This Row],[SKU]]="","",IFERROR(INDEX(tblProductos[Producto],MATCH(tblVentas[[#This Row],[SKU]],tblProductos[SKU],0))&" "&INDEX(tblProductos[Talla],MATCH(tblVentas[[#This Row],[SKU]],tblProductos[SKU],0)),"SKU no existe")) -> Pijama Niño 10 | E7: 1 | F7: =IF(tblVentas[[#This Row],[SKU]]="","",IFERROR(INDEX(tblProductos[Precio venta],MATCH(tblVentas[[#This Row],[SKU]],tblProductos[SKU],0)),0)) -> 10 | G7: -2 | H7: =IF(OR(tblVentas[[#This Row],[SKU]]="",tblVentas[[#This Row],[Cantidad]]=""),"",tblVentas[[#This Row],[Cantidad]]*tblVentas[[#This Row],[Precio unitario]]-tblVentas[[#This Row],[Descuento]]) -> 12 | I7: =IF(OR(tblVentas[[#This Row],[SKU]]="",tblVentas[[#This Row],[Cantidad]]=""),"",tblVentas[[#This Row],[Cantidad]]*IFERROR(INDEX(tblProductos[Costo unitario],MATCH(tblVentas[[#This Row],[SKU]],tblProductos[SKU],0)),0)) -> 5 | J7: =IF(tblVentas[[#This Row],[Total venta]]="","",tblVentas[[#This Row],[Total venta]]-tblVentas[[#This Row],[Costo]]) -> 7 | K7: WhatsApp | L7: Silvia Guerrero | M7: Entregado | N7: =IF(tblVentas[[#This Row],[SKU]]="","",IF(ISNA(MATCH(tblVentas[[#This Row],[SKU]],tblProductos[SKU],0)),"SKU no registrado",IF(INDEX(tblProductos[Stock actual],MATCH(tblVentas[[#This Row],[SKU]],tblProductos[SKU],0))<0,"Stock insuficiente","")))
A8: 46312 | B8: 2 | C8: PJ-N-12 | D8: =IF(tblVentas[[#This Row],[SKU]]="","",IFERROR(INDEX(tblProductos[Producto],MATCH(tblVentas[[#This Row],[SKU]],tblProductos[SKU],0))&" "&INDEX(tblProductos[Talla],MATCH(tblVentas[[#This Row],[SKU]],tblProductos[SKU],0)),"SKU no existe")) -> Pijama Niño 12 | E8: 1 | F8: =IF(tblVentas[[#This Row],[SKU]]="","",IFERROR(INDEX(tblProductos[Precio venta],MATCH(tblVentas[[#This Row],[SKU]],tblProductos[SKU],0)),0)) -> 10 | G8: -2 | H8: =IF(OR(tblVentas[[#This Row],[SKU]]="",tblVentas[[#This Row],[Cantidad]]=""),"",tblVentas[[#This Row],[Cantidad]]*tblVentas[[#This Row],[Precio unitario]]-tblVentas[[#This Row],[Descuento]]) -> 12 | I8: =IF(OR(tblVentas[[#This Row],[SKU]]="",tblVentas[[#This Row],[Cantidad]]=""),"",tblVentas[[#This Row],[Cantidad]]*IFERROR(INDEX(tblProductos[Costo unitario],MATCH(tblVentas[[#This Row],[SKU]],tblProductos[SKU],0)),0)) -> 5 | J8: =IF(tblVentas[[#This Row],[Total venta]]="","",tblVentas[[#This Row],[Total venta]]-tblVentas[[#This Row],[Costo]]) -> 7 | K8: WhatsApp | L8: Silvia Guerrero | M8: Entregado | N8: =IF(tblVentas[[#This Row],[SKU]]="","",IF(ISNA(MATCH(tblVentas[[#This Row],[SKU]],tblProductos[SKU],0)),"SKU no registrado",IF(INDEX(tblProductos[Stock actual],MATCH(tblVentas[[#This Row],[SKU]],tblProductos[SKU],0))<0,"Stock insuficiente","")))
A9: 46312 | B9: 2 | C9: PJ-M-S | D9: =IF(tblVentas[[#This Row],[SKU]]="","",IFERROR(INDEX(tblProductos[Producto],MATCH(tblVentas[[#This Row],[SKU]],tblProductos[SKU],0))&" "&INDEX(tblProductos[Talla],MATCH(tblVentas[[#This Row],[SKU]],tblProductos[SKU],0)),"SKU no existe")) -> Pijama Mujer S | E9: 1 | F9: =IF(tblVentas[[#This Row],[SKU]]="","",IFERROR(INDEX(tblProductos[Precio venta],MATCH(tblVentas[[#This Row],[SKU]],tblProductos[SKU],0)),0)) -> 12 | G9: -3 | H9: =IF(OR(tblVentas[[#This Row],[SKU]]="",tblVentas[[#This Row],[Cantidad]]=""),"",tblVentas[[#This Row],[Cantidad]]*tblVentas[[#This Row],[Precio unitario]]-tblVentas[[#This Row],[Descuento]]) -> 15 | I9: =IF(OR(tblVentas[[#This Row],[SKU]]="",tblVentas[[#This Row],[Cantidad]]=""),"",tblVentas[[#This Row],[Cantidad]]*IFERROR(INDEX(tblProductos[Costo unitario],MATCH(tblVentas[[#This Row],[SKU]],tblProductos[SKU],0)),0)) -> 8.5 | J9: =IF(tblVentas[[#This Row],[Total venta]]="","",tblVentas[[#This Row],[Total venta]]-tblVentas[[#This Row],[Costo]]) -> 6.5 | K9: WhatsApp | L9: Silvia Guerrero | M9: Entregado | N9: =IF(tblVentas[[#This Row],[SKU]]="","",IF(ISNA(MATCH(tblVentas[[#This Row],[SKU]],tblProductos[SKU],0)),"SKU no registrado",IF(INDEX(tblProductos[Stock actual],MATCH(tblVentas[[#This Row],[SKU]],tblProductos[SKU],0))<0,"Stock insuficiente","")))
A10: 46316 | B10: 3 | C10: PJ-M-S | D10: =IF(tblVentas[[#This Row],[SKU]]="","",IFERROR(INDEX(tblProductos[Producto],MATCH(tblVentas[[#This Row],[SKU]],tblProductos[SKU],0))&" "&INDEX(tblProductos[Talla],MATCH(tblVentas[[#This Row],[SKU]],tblProductos[SKU],0)),"SKU no existe")) -> Pijama Mujer S | E10: 1 | F10: =IF(tblVentas[[#This Row],[SKU]]="","",IFERROR(INDEX(tblProductos[Precio venta],MATCH(tblVentas[[#This Row],[SKU]],tblProductos[SKU],0)),0)) -> 12 | G10: -3 | H10: =IF(OR(tblVentas[[#This Row],[SKU]]="",tblVentas[[#This Row],[Cantidad]]=""),"",tblVentas[[#This Row],[Cantidad]]*tblVentas[[#This Row],[Precio unitario]]-tblVentas[[#This Row],[Descuento]]) -> 15 | I10: =IF(OR(tblVentas[[#This Row],[SKU]]="",tblVentas[[#This Row],[Cantidad]]=""),"",tblVentas[[#This Row],[Cantidad]]*IFERROR(INDEX(tblProductos[Costo unitario],MATCH(tblVentas[[#This Row],[SKU]],tblProductos[SKU],0)),0)) -> 8.5 | J10: =IF(tblVentas[[#This Row],[Total venta]]="","",tblVentas[[#This Row],[Total venta]]-tblVentas[[#This Row],[Costo]]) -> 6.5 | K10: WhatsApp | L10: Chambita | M10: Entregado | N10: =IF(tblVentas[[#This Row],[SKU]]="","",IF(ISNA(MATCH(tblVentas[[#This Row],[SKU]],tblProductos[SKU],0)),"SKU no registrado",IF(INDEX(tblProductos[Stock actual],MATCH(tblVentas[[#This Row],[SKU]],tblProductos[SKU],0))<0,"Stock insuficiente","")))
A11: 46316 | B11: 3 | C11: PJ-M-M | D11: =IF(tblVentas[[#This Row],[SKU]]="","",IFERROR(INDEX(tblProductos[Producto],MATCH(tblVentas[[#This Row],[SKU]],tblProductos[SKU],0))&" "&INDEX(tblProductos[Talla],MATCH(tblVentas[[#This Row],[SKU]],tblProductos[SKU],0)),"SKU no existe")) -> Pijama Mujer M | E11: 1 | F11: =IF(tblVentas[[#This Row],[SKU]]="","",IFERROR(INDEX(tblProductos[Precio venta],MATCH(tblVentas[[#This Row],[SKU]],tblProductos[SKU],0)),0)) -> 12 | G11: -3 | H11: =IF(OR(tblVentas[[#This Row],[SKU]]="",tblVentas[[#This Row],[Cantidad]]=""),"",tblVentas[[#This Row],[Cantidad]]*tblVentas[[#This Row],[Precio unitario]]-tblVentas[[#This Row],[Descuento]]) -> 15 | I11: =IF(OR(tblVentas[[#This Row],[SKU]]="",tblVentas[[#This Row],[Cantidad]]=""),"",tblVentas[[#This Row],[Cantidad]]*IFERROR(INDEX(tblProductos[Costo unitario],MATCH(tblVentas[[#This Row],[SKU]],tblProductos[SKU],0)),0)) -> 8.5 | J11: =IF(tblVentas[[#This Row],[Total venta]]="","",tblVentas[[#This Row],[Total venta]]-tblVentas[[#This Row],[Costo]]) -> 6.5 | K11: WhatsApp | L11: Chambita | M11: Entregado | N11: =IF(tblVentas[[#This Row],[SKU]]="","",IF(ISNA(MATCH(tblVentas[[#This Row],[SKU]],tblProductos[SKU],0)),"SKU no registrado",IF(INDEX(tblProductos[Stock actual],MATCH(tblVentas[[#This Row],[SKU]],tblProductos[SKU],0))<0,"Stock insuficiente","")))
A12: 46312 | B12: 4 | C12: PJ-M-L | D12: =IF(tblVentas[[#This Row],[SKU]]="","",IFERROR(INDEX(tblProductos[Producto],MATCH(tblVentas[[#This Row],[SKU]],tblProductos[SKU],0))&" "&INDEX(tblProductos[Talla],MATCH(tblVentas[[#This Row],[SKU]],tblProductos[SKU],0)),"SKU no existe")) -> Pijama Mujer L | E12: 1 | F12: =IF(tblVentas[[#This Row],[SKU]]="","",IFERROR(INDEX(tblProductos[Precio venta],MATCH(tblVentas[[#This Row],[SKU]],tblProductos[SKU],0)),0)) -> 12 | G12: 0 | H12: =IF(OR(tblVentas[[#This Row],[SKU]]="",tblVentas[[#This Row],[Cantidad]]=""),"",tblVentas[[#This Row],[Cantidad]]*tblVentas[[#This Row],[Precio unitario]]-tblVentas[[#This Row],[Descuento]]) -> 12 | I12: =IF(OR(tblVentas[[#This Row],[SKU]]="",tblVentas[[#This Row],[Cantidad]]=""),"",tblVentas[[#This Row],[Cantidad]]*IFERROR(INDEX(tblProductos[Costo unitario],MATCH(tblVentas[[#This Row],[SKU]],tblProductos[SKU],0)),0)) -> 8.5 | J12: =IF(tblVentas[[#This Row],[Total venta]]="","",tblVentas[[#This Row],[Total venta]]-tblVentas[[#This Row],[Costo]]) -> 3.5 | K12: WhatsApp | L12: Roxana | M12: Entregado | N12: =IF(tblVentas[[#This Row],[SKU]]="","",IF(ISNA(MATCH(tblVentas[[#This Row],[SKU]],tblProductos[SKU],0)),"SKU no registrado",IF(INDEX(tblProductos[Stock actual],MATCH(tblVentas[[#This Row],[SKU]],tblProductos[SKU],0))<0,"Stock insuficiente","")))
A13: 46316 | B13: 5 | C13: PJ-M-M | D13: =IF(tblVentas[[#This Row],[SKU]]="","",IFERROR(INDEX(tblProductos[Producto],MATCH(tblVentas[[#This Row],[SKU]],tblProductos[SKU],0))&" "&INDEX(tblProductos[Talla],MATCH(tblVentas[[#This Row],[SKU]],tblProductos[SKU],0)),"SKU no existe")) -> Pijama Mujer M | E13: 1 | F13: =IF(tblVentas[[#This Row],[SKU]]="","",IFERROR(INDEX(tblProductos[Precio venta],MATCH(tblVentas[[#This Row],[SKU]],tblProductos[SKU],0)),0)) -> 12 | G13: -3 | H13: =IF(OR(tblVentas[[#This Row],[SKU]]="",tblVentas[[#This Row],[Cantidad]]=""),"",tblVentas[[#This Row],[Cantidad]]*tblVentas[[#This Row],[Precio unitario]]-tblVentas[[#This Row],[Descuento]]) -> 15 | I13: =IF(OR(tblVentas[[#This Row],[SKU]]="",tblVentas[[#This Row],[Cantidad]]=""),"",tblVentas[[#This Row],[Cantidad]]*IFERROR(INDEX(tblProductos[Costo unitario],MATCH(tblVentas[[#This Row],[SKU]],tblProductos[SKU],0)),0)) -> 8.5 | J13: =IF(tblVentas[[#This Row],[Total venta]]="","",tblVentas[[#This Row],[Total venta]]-tblVentas[[#This Row],[Costo]]) -> 6.5 | K13: WhatsApp | L13: Noita | M13: Entregado | N13: =IF(tblVentas[[#This Row],[SKU]]="","",IF(ISNA(MATCH(tblVentas[[#This Row],[SKU]],tblProductos[SKU],0)),"SKU no registrado",IF(INDEX(tblProductos[Stock actual],MATCH(tblVentas[[#This Row],[SKU]],tblProductos[SKU],0))<0,"Stock insuficiente","")))
A14: 46316 | B14: 5 | C14: PJ-M-S | D14: =IF(tblVentas[[#This Row],[SKU]]="","",IFERROR(INDEX(tblProductos[Producto],MATCH(tblVentas[[#This Row],[SKU]],tblProductos[SKU],0))&" "&INDEX(tblProductos[Talla],MATCH(tblVentas[[#This Row],[SKU]],tblProductos[SKU],0)),"SKU no existe")) -> Pijama Mujer S | E14: 1 | F14: =IF(tblVentas[[#This Row],[SKU]]="","",IFERROR(INDEX(tblProductos[Precio venta],MATCH(tblVentas[[#This Row],[SKU]],tblProductos[SKU],0)),0)) -> 12 | G14: 0 | H14: =IF(OR(tblVentas[[#This Row],[SKU]]="",tblVentas[[#This Row],[Cantidad]]=""),"",tblVentas[[#This Row],[Cantidad]]*tblVentas[[#This Row],[Precio unitario]]-tblVentas[[#This Row],[Descuento]]) -> 12 | I14: =IF(OR(tblVentas[[#This Row],[SKU]]="",tblVentas[[#This Row],[Cantidad]]=""),"",tblVentas[[#This Row],[Cantidad]]*IFERROR(INDEX(tblProductos[Costo unitario],MATCH(tblVentas[[#This Row],[SKU]],tblProductos[SKU],0)),0)) -> 8.5 | J14: =IF(tblVentas[[#This Row],[Total venta]]="","",tblVentas[[#This Row],[Total venta]]-tblVentas[[#This Row],[Costo]]) -> 3.5 | K14: WhatsApp | L14: Noita | M14: Pendiente | N14: =IF(tblVentas[[#This Row],[SKU]]="","",IF(ISNA(MATCH(tblVentas[[#This Row],[SKU]],tblProductos[SKU],0)),"SKU no registrado",IF(INDEX(tblProductos[Stock actual],MATCH(tblVentas[[#This Row],[SKU]],tblProductos[SKU],0))<0,"Stock insuficiente","")))
A15: 46321 | B15: 6 | C15: PJ-N-12 | D15: =IF(tblVentas[[#This Row],[SKU]]="","",IFERROR(INDEX(tblProductos[Producto],MATCH(tblVentas[[#This Row],[SKU]],tblProductos[SKU],0))&" "&INDEX(tblProductos[Talla],MATCH(tblVentas[[#This Row],[SKU]],tblProductos[SKU],0)),"SKU no existe")) -> Pijama Niño 12 | E15: 8 | F15: =IF(tblVentas[[#This Row],[SKU]]="","",IFERROR(INDEX(tblProductos[Precio venta],MATCH(tblVentas[[#This Row],[SKU]],tblProductos[SKU],0)),0)) -> 10 | G15: 0 | H15: =IF(OR(tblVentas[[#This Row],[SKU]]="",tblVentas[[#This Row],[Cantidad]]=""),"",tblVentas[[#This Row],[Cantidad]]*tblVentas[[#This Row],[Precio unitario]]-tblVentas[[#This Row],[Descuento]]) -> 80 | I15: =IF(OR(tblVentas[[#This Row],[SKU]]="",tblVentas[[#This Row],[Cantidad]]=""),"",tblVentas[[#This Row],[Cantidad]]*IFERROR(INDEX(tblProductos[Costo unitario],MATCH(tblVentas[[#This Row],[SKU]],tblProductos[SKU],0)),0)) -> 40 | J15: =IF(tblVentas[[#This Row],[Total venta]]="","",tblVentas[[#This Row],[Total venta]]-tblVentas[[#This Row],[Costo]]) -> 40 | L15: RUT | M15: Entregado | N15: =IF(tblVentas[[#This Row],[SKU]]="","",IF(ISNA(MATCH(tblVentas[[#This Row],[SKU]],tblProductos[SKU],0)),"SKU no registrado",IF(INDEX(tblProductos[Stock actual],MATCH(tblVentas[[#This Row],[SKU]],tblProductos[SKU],0))<0,"Stock insuficiente","")))
A16: 46321 | B16: 6 | C16: PJ-H-S | D16: =IF(tblVentas[[#This Row],[SKU]]="","",IFERROR(INDEX(tblProductos[Producto],MATCH(tblVentas[[#This Row],[SKU]],tblProductos[SKU],0))&" "&INDEX(tblProductos[Talla],MATCH(tblVentas[[#This Row],[SKU]],tblProductos[SKU],0)),"SKU no existe")) -> Pijama Hombre S | E16: 3 | F16: =IF(tblVentas[[#This Row],[SKU]]="","",IFERROR(INDEX(tblProductos[Precio venta],MATCH(tblVentas[[#This Row],[SKU]],tblProductos[SKU],0)),0)) -> 12 | G16: -4 | H16: =IF(OR(tblVentas[[#This Row],[SKU]]="",tblVentas[[#This Row],[Cantidad]]=""),"",tblVentas[[#This Row],[Cantidad]]*tblVentas[[#This Row],[Precio unitario]]-tblVentas[[#This Row],[Descuento]]) -> 40 | I16: =IF(OR(tblVentas[[#This Row],[SKU]]="",tblVentas[[#This Row],[Cantidad]]=""),"",tblVentas[[#This Row],[Cantidad]]*IFERROR(INDEX(tblProductos[Costo unitario],MATCH(tblVentas[[#This Row],[SKU]],tblProductos[SKU],0)),0)) -> 26.25 | J16: =IF(tblVentas[[#This Row],[Total venta]]="","",tblVentas[[#This Row],[Total venta]]-tblVentas[[#This Row],[Costo]]) -> 13.75 | L16: RUT | M16: Entregado | N16: =IF(tblVentas[[#This Row],[SKU]]="","",IF(ISNA(MATCH(tblVentas[[#This Row],[SKU]],tblProductos[SKU],0)),"SKU no registrado",IF(INDEX(tblProductos[Stock actual],MATCH(tblVentas[[#This Row],[SKU]],tblProductos[SKU],0))<0,"Stock insuficiente","")))
A17: 46321 | B17: 7 | C17: PJ-N-6 | D17: =IF(tblVentas[[#This Row],[SKU]]="","",IFERROR(INDEX(tblProductos[Producto],MATCH(tblVentas[[#This Row],[SKU]],tblProductos[SKU],0))&" "&INDEX(tblProductos[Talla],MATCH(tblVentas[[#This Row],[SKU]],tblProductos[SKU],0)),"SKU no existe")) -> Pijama Niño 6 | E17: 1 | F17: =IF(tblVentas[[#This Row],[SKU]]="","",IFERROR(INDEX(tblProductos[Precio venta],MATCH(tblVentas[[#This Row],[SKU]],tblProductos[SKU],0)),0)) -> 10 | G17: 1 | H17: =IF(OR(tblVentas[[#This Row],[SKU]]="",tblVentas[[#This Row],[Cantidad]]=""),"",tblVentas[[#This Row],[Cantidad]]*tblVentas[[#This Row],[Precio unitario]]-tblVentas[[#This Row],[Descuento]]) -> 9 | I17: =IF(OR(tblVentas[[#This Row],[SKU]]="",tblVentas[[#This Row],[Cantidad]]=""),"",tblVentas[[#This Row],[Cantidad]]*IFERROR(INDEX(tblProductos[Costo unitario],MATCH(tblVentas[[#This Row],[SKU]],tblProductos[SKU],0)),0)) -> 5 | J17: =IF(tblVentas[[#This Row],[Total venta]]="","",tblVentas[[#This Row],[Total venta]]-tblVentas[[#This Row],[Costo]]) -> 4 | L17: RUT | M17: Pendiente | N17: =IF(tblVentas[[#This Row],[SKU]]="","",IF(ISNA(MATCH(tblVentas[[#This Row],[SKU]],tblProductos[SKU],0)),"SKU no registrado",IF(INDEX(tblProductos[Stock actual],MATCH(tblVentas[[#This Row],[SKU]],tblProductos[SKU],0))<0,"Stock insuficiente","")))
A18: 46321 | B18: 7 | C18: PJ-N-8 | D18: =IF(tblVentas[[#This Row],[SKU]]="","",IFERROR(INDEX(tblProductos[Producto],MATCH(tblVentas[[#This Row],[SKU]],tblProductos[SKU],0))&" "&INDEX(tblProductos[Talla],MATCH(tblVentas[[#This Row],[SKU]],tblProductos[SKU],0)),"SKU no existe")) -> Pijama Niño 8 | E18: 2 | F18: =IF(tblVentas[[#This Row],[SKU]]="","",IFERROR(INDEX(tblProductos[Precio venta],MATCH(tblVentas[[#This Row],[SKU]],tblProductos[SKU],0)),0)) -> 10 | G18: 2 | H18: =IF(OR(tblVentas[[#This Row],[SKU]]="",tblVentas[[#This Row],[Cantidad]]=""),"",tblVentas[[#This Row],[Cantidad]]*tblVentas[[#This Row],[Precio unitario]]-tblVentas[[#This Row],[Descuento]]) -> 18 | I18: =IF(OR(tblVentas[[#This Row],[SKU]]="",tblVentas[[#This Row],[Cantidad]]=""),"",tblVentas[[#This Row],[Cantidad]]*IFERROR(INDEX(tblProductos[Costo unitario],MATCH(tblVentas[[#This Row],[SKU]],tblProductos[SKU],0)),0)) -> 10 | J18: =IF(tblVentas[[#This Row],[Total venta]]="","",tblVentas[[#This Row],[Total venta]]-tblVentas[[#This Row],[Costo]]) -> 8 | L18: RUT | M18: Pendiente | N18: =IF(tblVentas[[#This Row],[SKU]]="","",IF(ISNA(MATCH(tblVentas[[#This Row],[SKU]],tblProductos[SKU],0)),"SKU no registrado",IF(INDEX(tblProductos[Stock actual],MATCH(tblVentas[[#This Row],[SKU]],tblProductos[SKU],0))<0,"Stock insuficiente","")))
A19: 46321 | B19: 7 | C19: PJ-N-10 | D19: =IF(tblVentas[[#This Row],[SKU]]="","",IFERROR(INDEX(tblProductos[Producto],MATCH(tblVentas[[#This Row],[SKU]],tblProductos[SKU],0))&" "&INDEX(tblProductos[Talla],MATCH(tblVentas[[#This Row],[SKU]],tblProductos[SKU],0)),"SKU no existe")) -> Pijama Niño 10 | E19: 2 | F19: =IF(tblVentas[[#This Row],[SKU]]="","",IFERROR(INDEX(tblProductos[Precio venta],MATCH(tblVentas[[#This Row],[SKU]],tblProductos[SKU],0)),0)) -> 10 | G19: 2 | H19: =IF(OR(tblVentas[[#This Row],[SKU]]="",tblVentas[[#This Row],[Cantidad]]=""),"",tblVentas[[#This Row],[Cantidad]]*tblVentas[[#This Row],[Precio unitario]]-tblVentas[[#This Row],[Descuento]]) -> 18 | I19: =IF(OR(tblVentas[[#This Row],[SKU]]="",tblVentas[[#This Row],[Cantidad]]=""),"",tblVentas[[#This Row],[Cantidad]]*IFERROR(INDEX(tblProductos[Costo unitario],MATCH(tblVentas[[#This Row],[SKU]],tblProductos[SKU],0)),0)) -> 10 | J19: =IF(tblVentas[[#This Row],[Total venta]]="","",tblVentas[[#This Row],[Total venta]]-tblVentas[[#This Row],[Costo]]) -> 8 | L19: RUT | M19: Pendiente | N19: =IF(tblVentas[[#This Row],[SKU]]="","",IF(ISNA(MATCH(tblVentas[[#This Row],[SKU]],tblProductos[SKU],0)),"SKU no registrado",IF(INDEX(tblProductos[Stock actual],MATCH(tblVentas[[#This Row],[SKU]],tblProductos[SKU],0))<0,"Stock insuficiente","")))
A20: 46321 | B20: 7 | C20: PJ-N-14 | D20: =IF(tblVentas[[#This Row],[SKU]]="","",IFERROR(INDEX(tblProductos[Producto],MATCH(tblVentas[[#This Row],[SKU]],tblProductos[SKU],0))&" "&INDEX(tblProductos[Talla],MATCH(tblVentas[[#This Row],[SKU]],tblProductos[SKU],0)),"SKU no existe")) -> Pijama Niño 14 | E20: 2 | F20: =IF(tblVentas[[#This Row],[SKU]]="","",IFERROR(INDEX(tblProductos[Precio venta],MATCH(tblVentas[[#This Row],[SKU]],tblProductos[SKU],0)),0)) -> 10 | G20: 2 | H20: =IF(OR(tblVentas[[#This Row],[SKU]]="",tblVentas[[#This Row],[Cantidad]]=""),"",tblVentas[[#This Row],[Cantidad]]*tblVentas[[#This Row],[Precio unitario]]-tblVentas[[#This Row],[Descuento]]) -> 18 | I20: =IF(OR(tblVentas[[#This Row],[SKU]]="",tblVentas[[#This Row],[Cantidad]]=""),"",tblVentas[[#This Row],[Cantidad]]*IFERROR(INDEX(tblProductos[Costo unitario],MATCH(tblVentas[[#This Row],[SKU]],tblProductos[SKU],0)),0)) -> 10 | J20: =IF(tblVentas[[#This Row],[Total venta]]="","",tblVentas[[#This Row],[Total venta]]-tblVentas[[#This Row],[Costo]]) -> 8 | L20: RUT | M20: Pendiente | N20: =IF(tblVentas[[#This Row],[SKU]]="","",IF(ISNA(MATCH(tblVentas[[#This Row],[SKU]],tblProductos[SKU],0)),"SKU no registrado",IF(INDEX(tblProductos[Stock actual],MATCH(tblVentas[[#This Row],[SKU]],tblProductos[SKU],0))<0,"Stock insuficiente","")))
A21: 46321 | B21: 7 | C21: PJ-M-S | D21: =IF(tblVentas[[#This Row],[SKU]]="","",IFERROR(INDEX(tblProductos[Producto],MATCH(tblVentas[[#This Row],[SKU]],tblProductos[SKU],0))&" "&INDEX(tblProductos[Talla],MATCH(tblVentas[[#This Row],[SKU]],tblProductos[SKU],0)),"SKU no existe")) -> Pijama Mujer S | E21: 1 | F21: =IF(tblVentas[[#This Row],[SKU]]="","",IFERROR(INDEX(tblProductos[Precio venta],MATCH(tblVentas[[#This Row],[SKU]],tblProductos[SKU],0)),0)) -> 12 | G21: 0 | H21: =IF(OR(tblVentas[[#This Row],[SKU]]="",tblVentas[[#This Row],[Cantidad]]=""),"",tblVentas[[#This Row],[Cantidad]]*tblVentas[[#This Row],[Precio unitario]]-tblVentas[[#This Row],[Descuento]]) -> 12 | I21: =IF(OR(tblVentas[[#This Row],[SKU]]="",tblVentas[[#This Row],[Cantidad]]=""),"",tblVentas[[#This Row],[Cantidad]]*IFERROR(INDEX(tblProductos[Costo unitario],MATCH(tblVentas[[#This Row],[SKU]],tblProductos[SKU],0)),0)) -> 8.5 | J21: =IF(tblVentas[[#This Row],[Total venta]]="","",tblVentas[[#This Row],[Total venta]]-tblVentas[[#This Row],[Costo]]) -> 3.5 | L21: RUT | M21: Pendiente | N21: =IF(tblVentas[[#This Row],[SKU]]="","",IF(ISNA(MATCH(tblVentas[[#This Row],[SKU]],tblProductos[SKU],0)),"SKU no registrado",IF(INDEX(tblProductos[Stock actual],MATCH(tblVentas[[#This Row],[SKU]],tblProductos[SKU],0))<0,"Stock insuficiente","")))
A22: 46321 | B22: 7 | C22: PJ-M-M | D22: =IF(tblVentas[[#This Row],[SKU]]="","",IFERROR(INDEX(tblProductos[Producto],MATCH(tblVentas[[#This Row],[SKU]],tblProductos[SKU],0))&" "&INDEX(tblProductos[Talla],MATCH(tblVentas[[#This Row],[SKU]],tblProductos[SKU],0)),"SKU no existe")) -> Pijama Mujer M | E22: 1 | F22: =IF(tblVentas[[#This Row],[SKU]]="","",IFERROR(INDEX(tblProductos[Precio venta],MATCH(tblVentas[[#This Row],[SKU]],tblProductos[SKU],0)),0)) -> 12 | G22: 0 | H22: =IF(OR(tblVentas[[#This Row],[SKU]]="",tblVentas[[#This Row],[Cantidad]]=""),"",tblVentas[[#This Row],[Cantidad]]*tblVentas[[#This Row],[Precio unitario]]-tblVentas[[#This Row],[Descuento]]) -> 12 | I22: =IF(OR(tblVentas[[#This Row],[SKU]]="",tblVentas[[#This Row],[Cantidad]]=""),"",tblVentas[[#This Row],[Cantidad]]*IFERROR(INDEX(tblProductos[Costo unitario],MATCH(tblVentas[[#This Row],[SKU]],tblProductos[SKU],0)),0)) -> 8.5 | J22: =IF(tblVentas[[#This Row],[Total venta]]="","",tblVentas[[#This Row],[Total venta]]-tblVentas[[#This Row],[Costo]]) -> 3.5 | L22: RUT | M22: Pendiente | N22: =IF(tblVentas[[#This Row],[SKU]]="","",IF(ISNA(MATCH(tblVentas[[#This Row],[SKU]],tblProductos[SKU],0)),"SKU no registrado",IF(INDEX(tblProductos[Stock actual],MATCH(tblVentas[[#This Row],[SKU]],tblProductos[SKU],0))<0,"Stock insuficiente","")))
A23: 46321 | B23: 7 | C23: PJ-M-XL | D23: =IF(tblVentas[[#This Row],[SKU]]="","",IFERROR(INDEX(tblProductos[Producto],MATCH(tblVentas[[#This Row],[SKU]],tblProductos[SKU],0))&" "&INDEX(tblProductos[Talla],MATCH(tblVentas[[#This Row],[SKU]],tblProductos[SKU],0)),"SKU no existe")) -> Pijama Mujer XL | E23: 2 | F23: =IF(tblVentas[[#This Row],[SKU]]="","",IFERROR(INDEX(tblProductos[Precio venta],MATCH(tblVentas[[#This Row],[SKU]],tblProductos[SKU],0)),0)) -> 12 | G23: 1 | H23: =IF(OR(tblVentas[[#This Row],[SKU]]="",tblVentas[[#This Row],[Cantidad]]=""),"",tblVentas[[#This Row],[Cantidad]]*tblVentas[[#This Row],[Precio unitario]]-tblVentas[[#This Row],[Descuento]]) -> 23 | I23: =IF(OR(tblVentas[[#This Row],[SKU]]="",tblVentas[[#This Row],[Cantidad]]=""),"",tblVentas[[#This Row],[Cantidad]]*IFERROR(INDEX(tblProductos[Costo unitario],MATCH(tblVentas[[#This Row],[SKU]],tblProductos[SKU],0)),0)) -> 17 | J23: =IF(tblVentas[[#This Row],[Total venta]]="","",tblVentas[[#This Row],[Total venta]]-tblVentas[[#This Row],[Costo]]) -> 6 | L23: RUT | M23: Pendiente | N23: =IF(tblVentas[[#This Row],[SKU]]="","",IF(ISNA(MATCH(tblVentas[[#This Row],[SKU]],tblProductos[SKU],0)),"SKU no registrado",IF(INDEX(tblProductos[Stock actual],MATCH(tblVentas[[#This Row],[SKU]],tblProductos[SKU],0))<0,"Stock insuficiente","")))
A24: 46321 | B24: 7 | C24: PJ-H-L | D24: =IF(tblVentas[[#This Row],[SKU]]="","",IFERROR(INDEX(tblProductos[Producto],MATCH(tblVentas[[#This Row],[SKU]],tblProductos[SKU],0))&" "&INDEX(tblProductos[Talla],MATCH(tblVentas[[#This Row],[SKU]],tblProductos[SKU],0)),"SKU no existe")) -> Pijama Hombre L | E24: 2 | F24: =IF(tblVentas[[#This Row],[SKU]]="","",IFERROR(INDEX(tblProductos[Precio venta],MATCH(tblVentas[[#This Row],[SKU]],tblProductos[SKU],0)),0)) -> 12 | G24: 1 | H24: =IF(OR(tblVentas[[#This Row],[SKU]]="",tblVentas[[#This Row],[Cantidad]]=""),"",tblVentas[[#This Row],[Cantidad]]*tblVentas[[#This Row],[Precio unitario]]-tblVentas[[#This Row],[Descuento]]) -> 23 | I24: =IF(OR(tblVentas[[#This Row],[SKU]]="",tblVentas[[#This Row],[Cantidad]]=""),"",tblVentas[[#This Row],[Cantidad]]*IFERROR(INDEX(tblProductos[Costo unitario],MATCH(tblVentas[[#This Row],[SKU]],tblProductos[SKU],0)),0)) -> 17.5 | J24: =IF(tblVentas[[#This Row],[Total venta]]="","",tblVentas[[#This Row],[Total venta]]-tblVentas[[#This Row],[Costo]]) -> 5.5 | L24: RUT | M24: Pendiente | N24: =IF(tblVentas[[#This Row],[SKU]]="","",IF(ISNA(MATCH(tblVentas[[#This Row],[SKU]],tblProductos[SKU],0)),"SKU no registrado",IF(INDEX(tblProductos[Stock actual],MATCH(tblVentas[[#This Row],[SKU]],tblProductos[SKU],0))<0,"Stock insuficiente","")))
A25: 46321 | B25: 7 | C25: PJ-H-XL | D25: =IF(tblVentas[[#This Row],[SKU]]="","",IFERROR(INDEX(tblProductos[Producto],MATCH(tblVentas[[#This Row],[SKU]],tblProductos[SKU],0))&" "&INDEX(tblProductos[Talla],MATCH(tblVentas[[#This Row],[SKU]],tblProductos[SKU],0)),"SKU no existe")) -> Pijama Hombre XL | E25: 2 | F25: =IF(tblVentas[[#This Row],[SKU]]="","",IFERROR(INDEX(tblProductos[Precio venta],MATCH(tblVentas[[#This Row],[SKU]],tblProductos[SKU],0)),0)) -> 12 | G25: 1 | H25: =IF(OR(tblVentas[[#This Row],[SKU]]="",tblVentas[[#This Row],[Cantidad]]=""),"",tblVentas[[#This Row],[Cantidad]]*tblVentas[[#This Row],[Precio unitario]]-tblVentas[[#This Row],[Descuento]]) -> 23 | I25: =IF(OR(tblVentas[[#This Row],[SKU]]="",tblVentas[[#This Row],[Cantidad]]=""),"",tblVentas[[#This Row],[Cantidad]]*IFERROR(INDEX(tblProductos[Costo unitario],MATCH(tblVentas[[#This Row],[SKU]],tblProductos[SKU],0)),0)) -> 17.5 | J25: =IF(tblVentas[[#This Row],[Total venta]]="","",tblVentas[[#This Row],[Total venta]]-tblVentas[[#This Row],[Costo]]) -> 5.5 | L25: RUT | M25: Pendiente | N25: =IF(tblVentas[[#This Row],[SKU]]="","",IF(ISNA(MATCH(tblVentas[[#This Row],[SKU]],tblProductos[SKU],0)),"SKU no registrado",IF(INDEX(tblProductos[Stock actual],MATCH(tblVentas[[#This Row],[SKU]],tblProductos[SKU],0))<0,"Stock insuficiente","")))
A26: 46321 | B26: 7 | C26: PJ-H-XXL | D26: =IF(tblVentas[[#This Row],[SKU]]="","",IFERROR(INDEX(tblProductos[Producto],MATCH(tblVentas[[#This Row],[SKU]],tblProductos[SKU],0))&" "&INDEX(tblProductos[Talla],MATCH(tblVentas[[#This Row],[SKU]],tblProductos[SKU],0)),"SKU no existe")) -> Pijama Hombre XXL | E26: 2 | F26: =IF(tblVentas[[#This Row],[SKU]]="","",IFERROR(INDEX(tblProductos[Precio venta],MATCH(tblVentas[[#This Row],[SKU]],tblProductos[SKU],0)),0)) -> 12 | G26: 1 | H26: =IF(OR(tblVentas[[#This Row],[SKU]]="",tblVentas[[#This Row],[Cantidad]]=""),"",tblVentas[[#This Row],[Cantidad]]*tblVentas[[#This Row],[Precio unitario]]-tblVentas[[#This Row],[Descuento]]) -> 23 | I26: =IF(OR(tblVentas[[#This Row],[SKU]]="",tblVentas[[#This Row],[Cantidad]]=""),"",tblVentas[[#This Row],[Cantidad]]*IFERROR(INDEX(tblProductos[Costo unitario],MATCH(tblVentas[[#This Row],[SKU]],tblProductos[SKU],0)),0)) -> 17.5 | J26: =IF(tblVentas[[#This Row],[Total venta]]="","",tblVentas[[#This Row],[Total venta]]-tblVentas[[#This Row],[Costo]]) -> 5.5 | L26: RUT | M26: Pendiente | N26: =IF(tblVentas[[#This Row],[SKU]]="","",IF(ISNA(MATCH(tblVentas[[#This Row],[SKU]],tblProductos[SKU],0)),"SKU no registrado",IF(INDEX(tblProductos[Stock actual],MATCH(tblVentas[[#This Row],[SKU]],tblProductos[SKU],0))<0,"Stock insuficiente","")))
A27: 46323 | B27: 261028-1212 | C27: PJ-N-10 | D27: =IF(tblVentas[[#This Row],[SKU]]="","",IFERROR(INDEX(tblProductos[Producto],MATCH(tblVentas[[#This Row],[SKU]],tblProductos[SKU],0))&" "&INDEX(tblProductos[Talla],MATCH(tblVentas[[#This Row],[SKU]],tblProductos[SKU],0)),"SKU no existe")) -> Pijama Niño 10 | E27: 1 | F27: =IF(tblVentas[[#This Row],[SKU]]="","",IFERROR(INDEX(tblProductos[Precio venta],MATCH(tblVentas[[#This Row],[SKU]],tblProductos[SKU],0)),0)) -> 10 | G27: 1 | H27: =IF(OR(tblVentas[[#This Row],[SKU]]="",tblVentas[[#This Row],[Cantidad]]=""),"",tblVentas[[#This Row],[Cantidad]]*tblVentas[[#This Row],[Precio unitario]]-tblVentas[[#This Row],[Descuento]]) -> 9 | I27: =IF(OR(tblVentas[[#This Row],[SKU]]="",tblVentas[[#This Row],[Cantidad]]=""),"",tblVentas[[#This Row],[Cantidad]]*IFERROR(INDEX(tblProductos[Costo unitario],MATCH(tblVentas[[#This Row],[SKU]],tblProductos[SKU],0)),0)) -> 5 | J27: =IF(tblVentas[[#This Row],[Total venta]]="","",tblVentas[[#This Row],[Total venta]]-tblVentas[[#This Row],[Costo]]) -> 4 | K27: WhatsApp | L27: Rosa Monterosa | M27: Pendiente | N27: =IF(tblVentas[[#This Row],[SKU]]="","",IF(ISNA(MATCH(tblVentas[[#This Row],[SKU]],tblProductos[SKU],0)),"SKU no registrado",IF(INDEX(tblProductos[Stock actual],MATCH(tblVentas[[#This Row],[SKU]],tblProductos[SKU],0))<0,"Stock insuficiente","")))
